Workbook

Sheet Sheet1
A1: route_start | B1: route_dest | C1: CODE | D1: id | E1: from_alternateId | I1: to_alternateId
A2: Pula Airport | B2: Poreč | C2: PUY | D2: 16447 | E2: 26134 | G2: Poreč | H2: 15658 | I2: 25346
A3: Pula Airport | B3: Pula | C3: PUY | D3: 16447 | E3: 26134 | G3: Pula | H3: 14395 | I3: 24087
A4: Pula Airport | B4: Pula, Bus Terminal | C4: PUY | D4: 16447 | E4: 26134 | G4: Pula Bus Terminal | H4: 14395 | I4: 24087
A5: Pula Airport | B5: Pula, Ferry Port | C5: PUY | D5: 16447 | E5: 26134 | G5: Pula Ferry Port | H5: 29468 | I5: 39036
A6: Pula Airport | B6: Lovran | C6: PUY | D6: 16447 | E6: 26134 | G6: Lovran | H6: 15389 | I6: 25077
A7: Pula Airport | B7: Medulin | C7: PUY | D7: 16447 | E7: 26134 | G7: Medulin | H7: 16450 | I7: 26137
A8: Pula Airport | B8: Novigrad, Istra | C8: PUY | D8: 16447 | E8: 26134 | G8: Novigrad Istra | H8: 15558 | I8: 25246
A9: Pula Airport | B9: Opatija | C9: PUY | D9: 16447 | E9: 26134 | G9: Opatija | H9: 15656 | I9: 25344
A10: Pula Airport | B10: Premantura | C10: PUY | D10: 16447 | E10: 26134 | G10: Premantura | H10: 16451 | I10: 26138
A11: Pula Airport | B11: Rabac | C11: PUY | D11: 16447 | E11: 26134 | G11: Rabac | H11: 16448 | I11: 26135
A12: Pula Airport | B12: Rijeka | C12: PUY | D12: 16447 | E12: 26134 | G12: Rijeka | H12: 15365 | I12: 25053
A13: Pula Airport | B13: Rovinj | C13: PUY | D13: 16447 | E13: 26134 | G13: Rovinj | H13: 15660 | I13: 25348
... A3346: Olbia Airport | B3346: Alghero Airport | C3346: OLB | D3346: 16704 | E3346: 26390 | G3346: Alghero Airport | H3346: 16684 | I3346: 26370
A3347: Olbia Airport | B3347: Cagliari Airport | C3347: OLB | D3347: 16704 | E3347: 26390 | G3347: Cagliari Airport | H3347: 16640, | I3347: 26326
A3348: Olbia Airport | B3348: Aglientu | C3348: OLB | D3348: 16704 | E3348: 26390 | G3348: Aglientu | H3348: 28411 | I3348: 37984
A3349: Olbia Airport | B3349: Santa Teresa Di Gallura | C3349: OLB | D3349: 16704 | E3349: 26390 | G3349: Santa Teresa Di Gallura | H3349: 28944, | I3349: 38514
A3350: Olbia Airport | B3350: Tortoli | C3350: OLB | D3350: 16704 | E3350: 26390 | G3350: Tortoli | H3350: 16679 | I3350: 26365
A3351: Olbia Airport | B3351: La Marmorata | C3351: OLB | D3351: 16704 | E3351: 26390 | G3351: La Marmorata | H3351: 16748 | I3351: 26434
A3352: Olbia Airport | B3352: Baja Sardinia | C3352: OLB | D3352: 16704 | E3352: 26390 | G3352: Baja Sardinia | H3352: 16724 | I3352: 26410
A3353: Olbia Airport | B3353: Sorso | C3353: OLB | D3353: 16704 | E3353: 26390 | G3353: Sorso | H3353: 24220 | I3353: 33808
A3354: Olbia Airport | B3354: Puntaldia | C3354: OLB | D3354: 16704 | E3354: 26390 | G3354: Puntaldia | H3354: 16719 | I3354: 26405
A3355: Olbia Airport | B3355: Stintino | C3355: OLB | D3355: 16704 | E3355: 26390 | G3355: Stintino | H3355: 16699 | I3355: 26385
A3356: Olbia Airport | B3356: Marinella Di Selinunte | C3356: OLB | D3356: 16704 | E3356: 26390 | G3356: MarinelLa Di Selinunte | H3356: 16711 | I3356: 26397
A3357: Olbia Airport | B3357: Marina Di Portisco | C3357: OLB | D3357: 16704 | E3357: 26390 | G3357: Marina Di Portisco | H3357: 16712 | I3357: 26398
A3358: Olbia Airport | B3358: Sos Alinos | C3358: OLB | D3358: 16704 | E3358: 26390 | G3358: Sos Alinos | H3358: 16670 | I3358: 26356
A3359: Olbia Airport | B3359: Capo D'orso | C3359: OLB | D3359: 16704 | E3359: 26390 | G3359: Capo D'orso | H3359: 16735 | I3359: 26421
A3360: Olbia Airport | B3360: Siniscola | C3360: OLB | D3360: 16704 | E3360: 26390 | G3360: Siniscola | H3360: 16746 | I3360: 26432
A3361: Olbia Airport | B3361: Porto Istana | C3361: OLB | D3361: 16704 | E3361: 26390 | G3361: Porto Istana | H3361: 16706 | I3361: 26392
... A3372: Olbia Airport | B3372: Porto Taverna | C3372: OLB | D3372: 16704 | E3372: 26390 | G3372: Porto Taverna | H3372: 16713 | I3372: 26399
A3373: Olbia Port | B3373: Olbia Airport | C3373: OLB | D3373: 16704 | E3373: 26390 | G3373: Olbia Airport | H3373: 16691, | I3373: 26377
A3374: Rotterdam Airport | B3374: Antwerpen | C3374: RTM | D3374: 15563 | E3374: 25251 | G3374: Antwerpen | H3374: 12712 | I3374: 22413
A3375: Rotterdam Airport | B3375: Brielle | C3375: RTM | D3375: 15563 | E3375: 25251 | G3375: Brielle | H3375: 15565 | I3375: 25253
A3376: Rotterdam Airport | B3376: Camping Duinrell | C3376: RTM | D3376: 15563 | E3376: 25251 | G3376: Camping Duinrell | H3376: 15593 | I3376: 25281
A3377: Rotterdam Airport | B3377: Camping Koningshof Bv | C3377: RTM | D3377: 15563 | E3377: 25251 | G3377: Camping Koningshof Bv | H3377: 19045 | I3377: 28689
A3378: Rotterdam Airport | B3378: Dordrecht | C3378: RTM | D3378: 15563 | E3378: 25251 | G3378: Dordrecht | H3378: 15568 | I3378: 25256
A3379: Rotterdam Airport | B3379: Eindhoven | C3379: RTM | D3379: 15563 | E3379: 25251 | G3379: Eindhoven | H3379: 12717 | I3379: 22418
A3380: Rotterdam Airport | B3380: Gouda | C3380: RTM | D3380: 15563 | E3380: 25251 | G3380: Gouda | H3380: 15569 | I3380: 25257
A3381: Rotterdam Airport | B3381: Leiden | C3381: RTM | D3381: 15563 | E3381: 25251 | G3381: Leiden | H3381: 15572 | I3381: 25260
A3382: Rotterdam Airport | B3382: Naaldwijk | C3382: RTM | D3382: 15563 | E3382: 25251 | G3382: Naaldwijk | H3382: 15576 | I3382: 25264
...

Sheet Sheet2
A1: Route start
A2: Pula Airport | B2: PUY
A3: Trieste Airport | B3: TRS
A4: Venice Marco Polo Airport | B4: VCE
A5: Rijeka, Ferry Port
A6: Portorož
A7: Rakalj
A8: Prizna
A9: Bled
A10: Rijeka Airport | B10: RJK
A11: Vienna Airport | B11: VIE
A12: Trieste Train Station
A13: Zagreb
A14: Pazin
A15: Zagreb Airport | B15: ZAG
A16: Mali Lošinj
A17: Budapest Airport | B17: BUD
A18: Split Airport | B18: SPU
A19: Prijedor
A20: Dubrovnik Airport | B20: DBV
A21: Zadar Airport | B21: ZAD
A22: Sarajevo Airport | B22: SJJ
A23: Blato, Korčula
A24: Gata
A25: Viganj
A26: Neum
A27: Tivat Airport | B27: TIV
A28: Stari Bar
A29: Kumbor
A30: Prague Airport | B30: PRG
A31: Bratislava Airport | B31: BTS
A32: Dresden
A33: Mikulov
A34: Oberlech
A35: Maribor
A36: Munich
A37: Nove Mesto, Slovakia
A38: Ljubljana Airport | B38: LJU
A39: Salzburg Airport | B39: SZG
A40: Hopfgarten Im Brixental
...

Sheet Sheet3
A1: Alicante airport | B1: Alicante Airport | C1: ALC | D1: 13 | E1: 10569 | H1: =VLOOKUP(C1,Sheet4!$C:$D,2,FALSE) -> Aviador C. Campos Airport | I1: ALC
A2: Almeria airport | B2: Almeria Airport | C2: LEI | D2: 15 | E2: 10570 | H2: =VLOOKUP(C2,Sheet4!$C:$D,2,FALSE) -> #N/A | I2: #N/A
A3: Barcelona airport | B3: Barcelona Airport | C3: BCN | D3: 32 | E3: 10571 | H3: =VLOOKUP(C3,Sheet4!$C:$D,2,FALSE) -> Barcelona | I3: BCN
A4: Girona airport | B4: Girona Airport | C4: GRO | D4: 138 | E4: 10100 | H4: =VLOOKUP(C4,Sheet4!$C:$D,2,FALSE) -> #N/A | I4: #N/A
A5: Granada airport | B5: Granada Airport | C5: GRX | D5: 141 | E5: 10573 | H5: =VLOOKUP(C5,Sheet4!$C:$D,2,FALSE) -> #N/A | I5: #N/A
A6: Ibiza airport | B6: Ibiza Airport | C6: IBZ | D6: 146 | E6: 10574 | H6: =VLOOKUP(C6,Sheet4!$C:$D,2,FALSE) -> #N/A | I6: #N/A
A7: Jerez airport | B7: Jerez Airport | C7: XRY | D7: 153 | E7: 10575 | H7: =VLOOKUP(C7,Sheet4!$C:$D,2,FALSE) -> #N/A | I7: #N/A
A8: Madrid airport | B8: Madrid Airport | C8: MAD | D8: 173 | E8: 10576 | H8: =VLOOKUP(C8,Sheet4!$C:$D,2,FALSE) -> Madrid | I8: MAD
A9: Malaga airport | B9: Malaga Airport | C9: AGP | D9: 177 | E9: 10577 | H9: =VLOOKUP(C9,Sheet4!$C:$D,2,FALSE) -> Malaga | I9: AGP
A10: Menorca airport | B10: Menorca Airport | C10: MAH | D10: 182 | E10: 10578 | H10: =VLOOKUP(C10,Sheet4!$C:$D,2,FALSE) -> #N/A | I10: #N/A
A11: Murcia airport | B11: Murcia Airport | C11: RMU | D11: 194 | E11: 10579 | H11: =VLOOKUP(C11,Sheet4!$C:$D,2,FALSE) -> #N/A | I11: #N/A
A12: Mallorca airport | B12: Mallorca Airport | C12: PMI | D12: 204 | E12: 10580 | H12: =VLOOKUP(C12,Sheet4!$C:$D,2,FALSE) -> Palma | I12: PMI
A13: Reus airport | B13: Reus Airport | C13: REU | D13: 240 | E13: 10581 | H13: =VLOOKUP(C13,Sheet4!$C:$D,2,FALSE) -> #N/A | I13: #N/A
A14: Seville airport | B14: Seville Airport | C14: SVQ | D14: 279 | E14: 10582 | H14: =VLOOKUP(C14,Sheet4!$C:$D,2,FALSE) -> #N/A | I14: #N/A
A15: Valencia airport | B15: Valencia Airport | C15: VLC | D15: 312 | E15: 10583 | H15: =VLOOKUP(C15,Sheet4!$C:$D,2,FALSE) -> #N/A | I15: #N/A
A16: Paris Beauvais airport | B16: Paris Beauvais Airport | C16: BVA | D16: 364 | E16: 10625 | H16: =VLOOKUP(C16,Sheet4!$C:$D,2,FALSE) -> #N/A | I16: #N/A
A17: Paris Charles de Gaulle airport | B17: Paris Charles de Gaulle Airport | C17: CDG | D17: 365 | E17: 10626 | H17: =VLOOKUP(C17,Sheet4!$C:$D,2,FALSE) -> Paris | I17: CDG
A18: Paris Orly airport | B18: Paris Orly Airport | C18: ORY | D18: 366 | E18: 10627 | H18: =VLOOKUP(C18,Sheet4!$C:$D,2,FALSE) -> #N/A | I18: #N/A
A19: Chambéry airport | B19: Chambéry Airport | C19: CMF | D19: 406 | E19: 10667 | H19: =VLOOKUP(C19,Sheet4!$C:$D,2,FALSE) -> #N/A | I19: #N/A
A20: Geneva airport | B20: Geneva Airport | C20: GVA | D20: 407 | E20: 10668 | H20: =VLOOKUP(C20,Sheet4!$C:$D,2,FALSE) -> Geneva | I20: GVA
A21: Lyon airport | B21: Lyon Airport | C21: LYS | D21: 408 | E21: 10669 | H21: =VLOOKUP(C21,Sheet4!$C:$D,2,FALSE) -> Lyon | I21: LYS
A22: Grenoble airport | B22: Grenoble Airport | C22: GNB | D22: 409 | E22: 10670 | H22: =VLOOKUP(C22,Sheet4!$C:$D,2,FALSE) -> #N/A | I22: #N/A
A23: Lisbon airport | B23: Lisbon Airport | C23: LIS | D23: 540 | E23: 10800 | H23: =VLOOKUP(C23,Sheet4!$C:$D,2,FALSE) -> Lisbon | I23: LIS
A24: Faro airport | B24: Faro Airport | C24: FAO | D24: 549 | E24: 10809 | H24: =VLOOKUP(C24,Sheet4!$C:$D,2,FALSE) -> #N/A | I24: #N/A
A25: Annecy airport | B25: Annecy Airport | C25: NCY | D25: 550 | E25: 10810 | H25: =VLOOKUP(C25,Sheet4!$C:$D,2,FALSE) -> #N/A | I25: #N/A
A26: Nice airport | B26: Nice Airport | C26: NCE | D26: 551 | E26: 10811 | H26: =VLOOKUP(C26,Sheet4!$C:$D,2,FALSE) -> #N/A | I26: #N/A
A27: Antalya airport | B27: Antalya Airport | C27: AYT | D27: 10906 | E27: 10902 | H27: =VLOOKUP(C27,Sheet4!$C:$D,2,FALSE) -> #N/A | I27: #N/A
A28: Malta airport | B28: Malta Airport | C28: MLA | D28: 10981 | E28: 10977 | H28: =VLOOKUP(C28,Sheet4!$C:$D,2,FALSE) -> Malta International Airport | I28: MLA
A29: Marrakech airport | B29: Marrakech Airport | C29: RAK | D29: 11001 | E29: 20710 | H29: =VLOOKUP(C29,Sheet4!$C:$D,2,FALSE) -> #N/A | I29: #N/A
A30: San Sebastián airport | B30: San Sebastián Airport | C30: EAS | D30: 11010 | E30: 20719 | H30: =VLOOKUP(C30,Sheet4!$C:$D,2,FALSE) -> San Sebastian Airport | I30: EAS
A31: Bilbao airport | B31: Bilbao Airport | C31: BIO | D31: 11020 | E31: 20729 | H31: =VLOOKUP(C31,Sheet4!$C:$D,2,FALSE) -> #N/A | I31: #N/A
A32: Santander airport | B32: Santander Airport | C32: SDR | D32: 11055 | E32: 20764 | H32: =VLOOKUP(C32,Sheet4!$C:$D,2,FALSE) -> #N/A | I32: #N/A
A33: Rhodes airport | B33: Rhodes Airport | C33: RHO | D33: 11642 | E33: 21351 | H33: =VLOOKUP(C33,Sheet4!$C:$D,2,FALSE) -> #N/A | I33: #N/A
A34: Kos airport | B34: Kos Airport | C34: KGS | D34: 11664 | E34: 21373 | H34: =VLOOKUP(C34,Sheet4!$C:$D,2,FALSE) -> #N/A | I34: #N/A
A35: Corfu airport | B35: Corfu Airport | C35: CFU | D35: 11677 | E35: 21386 | H35: =VLOOKUP(C35,Sheet4!$C:$D,2,FALSE) -> #N/A | I35: #N/A
A36: Casablanca airport | B36: Casablanca Airport | C36: CMN | D36: 11728 | E36: 21437 | H36: =VLOOKUP(C36,Sheet4!$C:$D,2,FALSE) -> #N/A | I36: #N/A
A37: Fez airport | B37: Fez Airport | C37: FEZ | D37: 11734 | E37: 21443 | H37: =VLOOKUP(C37,Sheet4!$C:$D,2,FALSE) -> #N/A | I37: #N/A
A38: Ouarzazate airport | B38: Ouarzazate Airport | C38: OZZ | D38: 11744 | E38: 21453 | H38: =VLOOKUP(C38,Sheet4!$C:$D,2,FALSE) -> #N/A | I38: #N/A
A39: Rabat airport | B39: Rabat Airport | C39: RBA | D39: 11745 | E39: 21454 | H39: =VLOOKUP(C39,Sheet4!$C:$D,2,FALSE) -> #N/A | I39: #N/A
A40: Agadir airport | B40: Agadir Airport | C40: AGA | D40: 11746 | E40: 21455 | H40: =VLOOKUP(C40,Sheet4!$C:$D,2,FALSE) -> #N/A | I40: #N/A
...

Sheet Sheet4
B1: Airport Name | C1: IATA Code | D1: ocation
B2: - | C2: - | D2: Prévessin-Moëns
B3: - | C3: - | D3: Port-Valais
B4: - | C4: - | D4: Breuil Cervinia
B5: - | C5: - | D5: Meyrin
B6: - | C6: - | D6: Unterseen
B7: - | C7: - | D7: Annemasse Train Station
B8: - | C8: - | D8: Ornex
B9: Bern Airport | C9: BRN | D9: Bern
B10: - | C10: - | D10: Bozel
B11: - | C11: - | D11: La Tour-De-Peilz
B12: - | C12: - | D12: Wettingen
... B556: Teresina Airport | C556: THE | D556: Teresina
